Workbook
Name _2012.06.11___GFM_Indicator_List: 'Indicator Metadata'!$D$18:$J$36
Name _2012.06.11___GFM_Indicator_List_1: 'Indicator Metadata'!$D$18:$J$36
Name _2012.06.11___GFM_Indicator_List_2: 'Indicator Metadata'!$D$16:$J$36
Name CrisisList: 'Crisis Indicator Data'!$A$13:$A$28
Name CrisisType: VLOOKUP(#REF!,#REF!,2,FALSE)
Name iCrisisType: INDIRECT(CrisisType)
Name iCrisisType: INDIRECT(CrisisType)
Name iCrisisType: INDIRECT(CrisisType)
Name iIcons_a5: INDIRECT(#REF!)
Name iIcons_a8: INDIRECT(#REF!)

Sheet About
A2: release:
A3: 30/04/2023
A4: INFORM SEVERITY INDEX
A5: April 2023
A6: OBJECTIVES AND PROCESS
A7: The INFORM Severity Index summarises a wide range of already existing, quantitative information about crisis severity and presents it in a format that can be used more easily in decision-making. It aggregates information from a range of credible, publicly available sources. Human analysts collect the data and enter it into the Index. It is intended to contribute to: - A shared and objective understanding of crisis severity; - Decisions on the allocation of resources in a way that is proportionate with crisis severity; - Justify and advocate for action, especially in the case of forgotten or unrecognised crises; - Monitor trends in crisis severity over time
A8: ANALYTICAL FRAMEWORK AND METHODOLOGY
A9: The INFORM Severity Index is a composite indicator that measures the severity of humanitarian crises against a common scale: It is a composite indicator that aggregates data from various sources to categorise all crises into five levels of severity: - Very high (5); High (4); Medium (3); Low (2); Very low (1) The Index covers: - The impact of the crisis itself, in terms of the scope of its geographical, human and physical effects; - The conditions and status of the people affected, including information about the distribution of severity (i.e. the number of people in each category of severity within a crisis); - The complexity of the crisis, in terms of factors that affect its mitigation or resolution. The results are provided by crisis and by country. A crisis is defined as an event and a location. There may be more than one crisis per country. Sometimes a crisis may be defined as a country. It is also possible to access the values for different levels of the analytical framework, to better understand the main drivers of a crisis. All the underlying data, metadata and methodology are publicly available.
A11: DATA SOURCES, USE AND LIMITATIONS
A12: The INFORM Severity aggregates information from a range of credible, publicly available sources, such as UN agencies, governments and other multilateral organisations. The country’s Humanitarian Needs Overview (HNO) is used if one is available. The INFORM Severity Index can be used to support decisions that require an understanding of the severity of crises globally or to understand changes in crisis severity over time. It should not be used for decisions about the operational response to a specific crisis. Crisis-specific information like needs assessments and appeals should be used to support these decisions. The INFORM Severity Index is only one source of information that can support decisions about humanitarian crises. It should typically be complemented by other sources. Due to the dynamic and chaotic nature of humanitarian emergencies and the lack of a globally systematic approach to data collection, imperfect information is necessarily used in the Index. Expert judgement is involved in deciding what data to include. A reliability estimate is provided for each crisis. The results spreadsheet contains metadata, showing the sources and dates of included figures, as well as key assessments or judgements made in their inclusion.
A13: FURTHER INFORMATION
A14: The development of the INFORM Severity Index was initiated and guided by the INFORM initiative - a multistakeholder partnership of humanitarian and development organisations, donors and technical partners - together with other interested organisations. The European Commission Joint Research Centre is responsible for the methodology. ACAPS is responsible for the data collection and analysis. OCHA is the overall coordinator of INFORM. We welcome all feedback and questions relating to the INFORM Severity INDEX. Please send them to contact@inform.index.org.
... A18: Citation INFORM. 2023. INFORM Severity Index April 2023. https://drmkc.jrc.ec.europa.eu/inform-index/INFORM-Severity. INFORM is a collaboration of the Inter-Agency Standing Committee Reference Group on Risk, Early Warning and Preparedness and the European Commission. The European Commission Joint Research Centre is responsible for the methodology. ACAPS is responsible for the data collection and analysis. OCHA is the overall coordinator of INFORM.

Sheet INFORM Severity - hidden
A2: CRISIS | B2: Website name | C2: CRISIS ID | D2: COUNTRY | E2: ISO3 | F2: DRIVERS | G2: INFORM Severity Index | H2: INFORM Severity category | I2: INFORM Severity category | J2: Trend (last 3 months) | K2: Reliability | L2: Impact of the crisis | M2: Geographical Impact | N2: Human Impact | O2: Conditions of people affected | P2: People in need | Q2: Concentration of conditions | R2: Complexity of the crisis | S2: Society and safety | T2: Operating environment | U2: Regions | V2: Last updated
A3: Weights | R3: 0.3
A4: (a-z) | E4: (a-z) | G4: (1-5) | H4: (1-5) | I4: (Very Low-Very High) | J4: (Decreasing-Stable-Increasing) | K4: (Very Low-Very High) | L4: (1-5) | M4: (1-5) | N4: (1-5) | O4: (1-5) | P4: (1-5) | Q4: (1-5) | R4: (1-5) | S4: (1-5) | T4: (1-5)
A5: ='Crisis Indicator Data'!A3 -> Complex crisis in Afghanistan | B5: =Lists!G3 -> Complex crisis | C5: ='Crisis Indicator Data'!C3 -> AFG001 | D5: ='Crisis Indicator Data'!D3 -> Afghanistan | E5: ='Crisis Indicator Data'!E3 -> AFG | F5: ='Crisis Indicator Data'!B3 -> Conflict,Violence,Displacement,Drought,Earthquake,Socio-political | G5: =IF(OR(O5="x",L5="x"),"x",ROUND((5-GEOMEAN(((5-L5)/5*4+1),((5-O5)/5*4+1),((5-O5)/5*4+1)))/4*3.5+R5*0.3,1)) -> 4.4 | H5: =IF(G5="x","x",ROUNDUP(G5,0)) -> 5 | I5: =IF(O5="x","x",IF(L5="x","x",(IF(H5=5,"Very High",IF(H5=4,"High",IF(H5=3,"Medium",IF(H5=2,"Low","Very Low"))))))) -> Very High | J5: =INDEX(Trends!$D$3:$D$404,MATCH(C5,Trends!$C$3:$C$404,0)) -> Stable | K5: =IF(Reliability!B3="x","x",(IF(ROUNDUP(Reliability!B3,0)=1,"Very High",IF(ROUNDUP(Reliability!B3,0)=2,"High",IF(ROUNDUP(Reliability!B3,0)=3,"Medium",IF(ROUNDUP(Reliability!B3,0)=4,"Low","Very Low")))))) -> High | L5: =IF(OR(N5="x",M5="x"),"x",ROUND((5-GEOMEAN(((5-M5)/5*4+1),((5-N5)/5*4+1),((5-N5)/5*4+1)))/4*5,1)) -> 4.6 | M5: ='Impact of the crisis'!N6 -> 4.9 | N5: ='Impact of the crisis'!AB6 -> 4.4 | O5: ='Conditions of people affected'!R6 -> 4.5 | P5: ='Conditions of people affected'!K6 -> 5 | Q5: ='Conditions of people affected'!Q6 -> 4 | R5: =IF(OR(T5="x",S5="x"),S5,ROUND((5-GEOMEAN(((5-S5)/5*4+1),((5-T5)/5*4+1)))/4*5,1)) -> 4.2 | S5: ='Complexity of the crisis'!X6 -> 3.9 | T5: ='Complexity of the crisis'!AN6 -> 4.5 | U5: =VLOOKUP(C5,Lists!$C$3:$E$200,3,FALSE) -> Asia | V5: 45046
A6: ='Crisis Indicator Data'!A4 -> Drought in South-West Angola | B6: =Lists!G4 -> Drought in South-West | C6: ='Crisis Indicator Data'!C4 -> AGO002 | D6: ='Crisis Indicator Data'!D4 -> Angola | E6: ='Crisis Indicator Data'!E4 -> AGO | F6: ='Crisis Indicator Data'!B4 -> Drought | G6: =IF(OR(O6="x",L6="x"),"x",ROUND((5-GEOMEAN(((5-L6)/5*4+1),((5-O6)/5*4+1),((5-O6)/5*4+1)))/4*3.5+R6*0.3,1)) -> 3.1 | H6: =IF(G6="x","x",ROUNDUP(G6,0)) -> 4 | I6: =IF(O6="x","x",IF(L6="x","x",(IF(H6=5,"Very High",IF(H6=4,"High",IF(H6=3,"Medium",IF(H6=2,"Low","Very Low"))))))) -> High | J6: =INDEX(Trends!$D$3:$D$404,MATCH(C6,Trends!$C$3:$C$404,0)) -> Stable | K6: =IF(Reliability!B4="x","x",(IF(ROUNDUP(Reliability!B4,0)=1,"Very High",IF(ROUNDUP(Reliability!B4,0)=2,"High",IF(ROUNDUP(Reliability!B4,0)=3,"Medium",IF(ROUNDUP(Reliability!B4,0)=4,"Low","Very Low")))))) -> High | L6: =IF(OR(N6="x",M6="x"),"x",ROUND((5-GEOMEAN(((5-M6)/5*4+1),((5-N6)/5*4+1),((5-N6)/5*4+1)))/4*5,1)) -> 2.8 | M6: ='Impact of the crisis'!N7 -> 3.7 | N6: ='Impact of the crisis'!AB7 -> 2.2 | O6: ='Conditions of people affected'!R7 -> 3.85 | P6: ='Conditions of people affected'!K7 -> 3.7 | Q6: ='Conditions of people affected'!Q7 -> 4 | R6: =IF(OR(T6="x",S6="x"),S6,ROUND((5-GEOMEAN(((5-S6)/5*4+1),((5-T6)/5*4+1)))/4*5,1)) -> 2.2 | S6: ='Complexity of the crisis'!X7 -> 3.1 | T6: ='Complexity of the crisis'!AN7 -> 1 | U6: =VLOOKUP(C6,Lists!$C$3:$E$200,3,FALSE) -> Africa | V6: 45043
A7: ='Crisis Indicator Data'!A5 -> Nagorno-Karabakh Conflict in Armenia | B7: =Lists!G5 -> Nagorno-Karabakh Conflict in Armenia | C7: ='Crisis Indicator Data'!C5 -> ARM002 | D7: ='Crisis Indicator Data'!D5 -> Armenia | E7: ='Crisis Indicator Data'!E5 -> ARM | F7: ='Crisis Indicator Data'!B5 -> Conflict,Displacement | G7: =IF(OR(O7="x",L7="x"),"x",ROUND((5-GEOMEAN(((5-L7)/5*4+1),((5-O7)/5*4+1),((5-O7)/5*4+1)))/4*3.5+R7*0.3,1)) -> 1.2 | H7: =IF(G7="x","x",ROUNDUP(G7,0)) -> 2 | I7: =IF(O7="x","x",IF(L7="x","x",(IF(H7=5,"Very High",IF(H7=4,"High",IF(H7=3,"Medium",IF(H7=2,"Low","Very Low"))))))) -> Low | J7: =INDEX(Trends!$D$3:$D$404,MATCH(C7,Trends!$C$3:$C$404,0)) -> Decreasing | K7: =IF(Reliability!B5="x","x",(IF(ROUNDUP(Reliability!B5,0)=1,"Very High",IF(ROUNDUP(Reliability!B5,0)=2,"High",IF(ROUNDUP(Reliability!B5,0)=3,"Medium",IF(ROUNDUP(Reliability!B5,0)=4,"Low","Very Low")))))) -> Medium | L7: =IF(OR(N7="x",M7="x"),"x",ROUND((5-GEOMEAN(((5-M7)/5*4+1),((5-N7)/5*4+1),((5-N7)/5*4+1)))/4*5,1)) -> 1.6 | M7: ='Impact of the crisis'!N8 -> 1.3 | N7: ='Impact of the crisis'!AB8 -> 1.8 | O7: ='Conditions of people affected'!R8 -> 0.85 | P7: ='Conditions of people affected'!K8 -> 0.7 | Q7: ='Conditions of people affected'!Q8 -> 1 | R7: =IF(OR(T7="x",S7="x"),S7,ROUND((5-GEOMEAN(((5-S7)/5*4+1),((5-T7)/5*4+1)))/4*5,1)) -> 1.4 | S7: ='Complexity of the crisis'!X8 -> 1.8 | T7: ='Complexity of the crisis'!AN8 -> 1 | U7: =VLOOKUP(C7,Lists!$C$3:$E$200,3,FALSE) -> Middle east | V7: 45046
A8: ='Crisis Indicator Data'!A6 -> Nagorno-Karabakh conflict in Azerbaijan | B8: =Lists!G6 -> Nagorno-Karabakh conflict in Azerbaijan | C8: ='Crisis Indicator Data'!C6 -> AZE002 | D8: ='Crisis Indicator Data'!D6 -> Azerbaijan | E8: ='Crisis Indicator Data'!E6 -> AZE | F8: ='Crisis Indicator Data'!B6 -> Conflict,Displacement | G8: =IF(OR(O8="x",L8="x"),"x",ROUND((5-GEOMEAN(((5-L8)/5*4+1),((5-O8)/5*4+1),((5-O8)/5*4+1)))/4*3.5+R8*0.3,1)) -> 1.8 | H8: =IF(G8="x","x",ROUNDUP(G8,0)) -> 2 | I8: =IF(O8="x","x",IF(L8="x","x",(IF(H8=5,"Very High",IF(H8=4,"High",IF(H8=3,"Medium",IF(H8=2,"Low","Very Low"))))))) -> Low | J8: =INDEX(Trends!$D$3:$D$404,MATCH(C8,Trends!$C$3:$C$404,0)) -> Stable | K8: =IF(Reliability!B6="x","x",(IF(ROUNDUP(Reliability!B6,0)=1,"Very High",IF(ROUNDUP(Reliability!B6,0)=2,"High",IF(ROUNDUP(Reliability!B6,0)=3,"Medium",IF(ROUNDUP(Reliability!B6,0)=4,"Low","Very Low")))))) -> Low | L8: =IF(OR(N8="x",M8="x"),"x",ROUND((5-GEOMEAN(((5-M8)/5*4+1),((5-N8)/5*4+1),((5-N8)/5*4+1)))/4*5,1)) -> 2.6 | M8: ='Impact of the crisis'!N9 -> 1.8 | N8: ='Impact of the crisis'!AB9 -> 3 | O8: ='Conditions of people affected'!R9 -> 1 | P8: ='Conditions of people affected'!K9 -> 0 | Q8: ='Conditions of people affected'!Q9 -> 2 | R8: =IF(OR(T8="x",S8="x"),S8,ROUND((5-GEOMEAN(((5-S8)/5*4+1),((5-T8)/5*4+1)))/4*5,1)) -> 2.3 | S8: ='Complexity of the crisis'!X9 -> 2.5 | T8: ='Complexity of the crisis'!AN9 -> 2 | U8: =VLOOKUP(C8,Lists!$C$3:$E$200,3,FALSE) -> Middle east | V8: 45046
A9: ='Crisis Indicator Data'!A7 -> Complex in Burundi | B9: =Lists!G7 -> Complex crisis | C9: ='Crisis Indicator Data'!C7 -> BDI001 | D9: ='Crisis Indicator Data'!D7 -> Burundi | E9: ='Crisis Indicator Data'!E7 -> BDI | F9: ='Crisis Indicator Data'!B7 -> Violence,Displacement,Floods | G9: =IF(OR(O9="x",L9="x"),"x",ROUND((5-GEOMEAN(((5-L9)/5*4+1),((5-O9)/5*4+1),((5-O9)/5*4+1)))/4*3.5+R9*0.3,1)) -> 3.5 | H9: =IF(G9="x","x",ROUNDUP(G9,0)) -> 4 | I9: =IF(O9="x","x",IF(L9="x","x",(IF(H9=5,"Very High",IF(H9=4,"High",IF(H9=3,"Medium",IF(H9=2,"Low","Very Low"))))))) -> High | J9: =INDEX(Trends!$D$3:$D$404,MATCH(C9,Trends!$C$3:$C$404,0)) -> Stable | K9: =IF(Reliability!B7="x","x",(IF(ROUNDUP(Reliability!B7,0)=1,"Very High",IF(ROUNDUP(Reliability!B7,0)=2,"High",IF(ROUNDUP(Reliability!B7,0)=3,"Medium",IF(ROUNDUP(Reliability!B7,0)=4,"Low","Very Low")))))) -> Very High | L9: =IF(OR(N9="x",M9="x"),"x",ROUND((5-GEOMEAN(((5-M9)/5*4+1),((5-N9)/5*4+1),((5-N9)/5*4+1)))/4*5,1)) -> 3.9 | M9: ='Impact of the crisis'!N10 -> 4 | N9: ='Impact of the crisis'!AB10 -> 3.8 | O9: ='Conditions of people affected'!R10 -> 3.4 | P9: ='Conditions of people affected'!K10 -> 3.8 | Q9: ='Conditions of people affected'!Q10 -> 3 | R9: =IF(OR(T9="x",S9="x"),S9,ROUND((5-GEOMEAN(((5-S9)/5*4+1),((5-T9)/5*4+1)))/4*5,1)) -> 3.3 | S9: ='Complexity of the crisis'!X10 -> 3 | T9: ='Complexity of the crisis'!AN10 -> 3.5 | U9: =VLOOKUP(C9,Lists!$C$3:$E$200,3,FALSE) -> Africa | V9: 45002
A10: ='Crisis Indicator Data'!A8 -> Conflict in Burkina Faso | B10: =Lists!G8 -> Conflict | C10: ='Crisis Indicator Data'!C8 -> BFA002 | D10: ='Crisis Indicator Data'!D8 -> Burkina Faso | E10: ='Crisis Indicator Data'!E8 -> BFA | F10: ='Crisis Indicator Data'!B8 -> Conflict,Displacement,Violence | G10: =IF(OR(O10="x",L10="x"),"x",ROUND((5-GEOMEAN(((5-L10)/5*4+1),((5-O10)/5*4+1),((5-O10)/5*4+1)))/4*3.5+R10*0.3,1)) -> 4 | H10: =IF(G10="x","x",ROUNDUP(G10,0)) -> 4 | I10: =IF(O10="x","x",IF(L10="x","x",(IF(H10=5,"Very High",IF(H10=4,"High",IF(H10=3,"Medium",IF(H10=2,"Low","Very Low"))))))) -> High | J10: =INDEX(Trends!$D$3:$D$404,MATCH(C10,Trends!$C$3:$C$404,0)) -> Increasing | K10: =IF(Reliability!B8="x","x",(IF(ROUNDUP(Reliability!B8,0)=1,"Very High",IF(ROUNDUP(Reliability!B8,0)=2,"High",IF(ROUNDUP(Reliability!B8,0)=3,"Medium",IF(ROUNDUP(Reliability!B8,0)=4,"Low","Very Low")))))) -> High | L10: =IF(OR(N10="x",M10="x"),"x",ROUND((5-GEOMEAN(((5-M10)/5*4+1),((5-N10)/5*4+1),((5-N10)/5*4+1)))/4*5,1)) -> 4.2 | M10: ='Impact of the crisis'!N11 -> 2.5 | N10: ='Impact of the crisis'!AB11 -> 4.7 | O10: ='Conditions of people affected'!R11 -> 4.15 | P10: ='Conditions of people affected'!K11 -> 4.3 | Q10: ='Conditions of people affected'!Q11 -> 4 | R10: =IF(OR(T10="x",S10="x"),S10,ROUND((5-GEOMEAN(((5-S10)/5*4+1),((5-T10)/5*4+1)))/4*5,1)) -> 3.6 | S10: ='Complexity of the crisis'!X11 -> 3.2 | T10: ='Complexity of the crisis'!AN11 -> 4 | U10: =VLOOKUP(C10,Lists!$C$3:$E$200,3,FALSE) -> Africa | V10: 45019
A11: ='Crisis Indicator Data'!A9 -> Rohingya refugee crisis | B11: =Lists!G9 -> Rohingya Refugees | C11: ='Crisis Indicator Data'!C9 -> BGD002 | D11: ='Crisis Indicator Data'!D9 -> Bangladesh | E11: ='Crisis Indicator Data'!E9 -> BGD | F11: ='Crisis Indicator Data'!B9 -> Conflict,Violence,Displacement | G11: =IF(OR(O11="x",L11="x"),"x",ROUND((5-GEOMEAN(((5-L11)/5*4+1),((5-O11)/5*4+1),((5-O11)/5*4+1)))/4*3.5+R11*0.3,1)) -> 3 | H11: =IF(G11="x","x",ROUNDUP(G11,0)) -> 3 | I11: =IF(O11="x","x",IF(L11="x","x",(IF(H11=5,"Very High",IF(H11=4,"High",IF(H11=3,"Medium",IF(H11=2,"Low","Very Low"))))))) -> Medium | J11: =INDEX(Trends!$D$3:$D$404,MATCH(C11,Trends!$C$3:$C$404,0)) -> Stable | K11: =IF(Reliability!B9="x","x",(IF(ROUNDUP(Reliability!B9,0)=1,"Very High",IF(ROUNDUP(Reliability!B9,0)=2,"High",IF(ROUNDUP(Reliability!B9,0)=3,"Medium",IF(ROUNDUP(Reliability!B9,0)=4,"Low","Very Low")))))) -> Very High | L11: =IF(OR(N11="x",M11="x"),"x",ROUND((5-GEOMEAN(((5-M11)/5*4+1),((5-N11)/5*4+1),((5-N11)/5*4+1)))/4*5,1)) -> 2.9 | M11: ='Impact of the crisis'!N12 -> 0.2 | N11: ='Impact of the crisis'!AB12 -> 3.8 | O11: ='Conditions of people affected'!R12 -> 3.3 | P11: ='Conditions of people affected'!K12 -> 3.6 | Q11: ='Conditions of people affected'!Q12 -> 3 | R11: =IF(OR(T11="x",S11="x"),S11,ROUND((5-GEOMEAN(((5-S11)/5*4+1),((5-T11)/5*4+1)))/4*5,1)) -> 2.6 | S11: ='Complexity of the crisis'!X12 -> 2.6 | T11: ='Complexity of the crisis'!AN12 -> 2.5 | U11: =VLOOKUP(C11,Lists!$C$3:$E$200,3,FALSE) -> Asia | V11: 45043
A12: ='Crisis Indicator Data'!A10 -> Country level Brazil | B12: =Lists!G10 -> Country level | C12: ='Crisis Indicator Data'!C10 -> BRA001 | D12: ='Crisis Indicator Data'!D10 -> Brazil | E12: ='Crisis Indicator Data'!E10 -> BRA | F12: ='Crisis Indicator Data'!B10 -> Displacement,Floods | G12: =IF(OR(O12="x",L12="x"),"x",ROUND((5-GEOMEAN(((5-L12)/5*4+1),((5-O12)/5*4+1),((5-O12)/5*4+1)))/4*3.5+R12*0.3,1)) -> 2.7 | H12: =IF(G12="x","x",ROUNDUP(G12,0)) -> 3 | I12: =IF(O12="x","x",IF(L12="x","x",(IF(H12=5,"Very High",IF(H12=4,"High",IF(H12=3,"Medium",IF(H12=2,"Low","Very Low"))))))) -> Medium | J12: =INDEX(Trends!$D$3:$D$404,MATCH(C12,Trends!$C$3:$C$404,0)) -> Decreasing | K12: =IF(Reliability!B10="x","x",(IF(ROUNDUP(Reliability!B10,0)=1,"Very High",IF(ROUNDUP(Reliability!B10,0)=2,"High",IF(ROUNDUP(Reliability!B10,0)=3,"Medium",IF(ROUNDUP(Reliability!B10,0)=4,"Low","Very Low")))))) -> Very High | L12: =IF(OR(N12="x",M12="x"),"x",ROUND((5-GEOMEAN(((5-M12)/5*4+1),((5-N12)/5*4+1),((5-N12)/5*4+1)))/4*5,1)) -> 3.9 | M12: ='Impact of the crisis'!N13 -> 4.4 | N12: ='Impact of the crisis'!AB13 -> 3.6 | O12: ='Conditions of people affected'!R13 -> 1.75 | P12: ='Conditions of people affected'!K13 -> 2.5 | Q12: ='Conditions of people affected'!Q13 -> 1 | R12: =IF(OR(T12="x",S12="x"),S12,ROUND((5-GEOMEAN(((5-S12)/5*4+1),((5-T12)/5*4+1)))/4*5,1)) -> 3 | S12: ='Complexity of the crisis'!X13 -> 2.9 | T12: ='Complexity of the crisis'!AN13 -> 3 | U12: =VLOOKUP(C12,Lists!$C$3:$E$200,3,FALSE) -> Americas | V12: 45017
A13: ='Crisis Indicator Data'!A11 -> Venezuela displacement in Brazil | B13: =Lists!G11 -> Venezuelan refugees | C13: ='Crisis Indicator Data'!C11 -> BRA002 | D13: ='Crisis Indicator Data'!D11 -> Brazil | E13: ='Crisis Indicator Data'!E11 -> BRA | F13: ='Crisis Indicator Data'!B11 -> Displacement | G13: =IF(OR(O13="x",L13="x"),"x",ROUND((5-GEOMEAN(((5-L13)/5*4+1),((5-O13)/5*4+1),((5-O13)/5*4+1)))/4*3.5+R13*0.3,1)) -> 2.7 | H13: =IF(G13="x","x",ROUNDUP(G13,0)) -> 3 | I13: =IF(O13="x","x",IF(L13="x","x",(IF(H13=5,"Very High",IF(H13=4,"High",IF(H13=3,"Medium",IF(H13=2,"Low","Very Low"))))))) -> Medium | J13: =INDEX(Trends!$D$3:$D$404,MATCH(C13,Trends!$C$3:$C$404,0)) -> Increasing | K13: =IF(Reliability!B11="x","x",(IF(ROUNDUP(Reliability!B11,0)=1,"Very High",IF(ROUNDUP(Reliability!B11,0)=2,"High",IF(ROUNDUP(Reliability!B11,0)=3,"Medium",IF(ROUNDUP(Reliability!B11,0)=4,"Low","Very Low")))))) -> Very High | L13: =IF(OR(N13="x",M13="x"),"x",ROUND((5-GEOMEAN(((5-M13)/5*4+1),((5-N13)/5*4+1),((5-N13)/5*4+1)))/4*5,1)) -> 3.8 | M13: ='Impact of the crisis'!N14 -> 4.4 | N13: ='Impact of the crisis'!AB14 -> 3.5 | O13: ='Conditions of people affected'!R14 -> 1.75 | P13: ='Conditions of people affected'!K14 -> 2.5 | Q13: ='Conditions of people affected'!Q14 -> 1 | R13: =IF(OR(T13="x",S13="x"),S13,ROUND((5-GEOMEAN(((5-S13)/5*4+1),((5-T13)/5*4+1)))/4*5,1)) -> 3 | S13: ='Complexity of the crisis'!X14 -> 2.9 | T13: ='Complexity of the crisis'!AN14 -> 3 | U13: =VLOOKUP(C13,Lists!$C$3:$E$200,3,FALSE) -> Americas | V13: 45015
A14: ='Crisis Indicator Data'!A12 -> Floods in rainy season 2022 | B14: =Lists!G12 -> Floods | C14: ='Crisis Indicator Data'!C12 -> BRA003 | D14: ='Crisis Indicator Data'!D12 -> Brazil | E14: ='Crisis Indicator Data'!E12 -> BRA | F14: ='Crisis Indicator Data'!B12 -> Floods | G14: =IF(OR(O14="x",L14="x"),"x",ROUND((5-GEOMEAN(((5-L14)/5*4+1),((5-O14)/5*4+1),((5-O14)/5*4+1)))/4*3.5+R14*0.3,1)) -> 1.6 | H14: =IF(G14="x","x",ROUNDUP(G14,0)) -> 2 | I14: =IF(O14="x","x",IF(L14="x","x",(IF(H14=5,"Very High",IF(H14=4,"High",IF(H14=3,"Medium",IF(H14=2,"Low","Very Low"))))))) -> Low | J14: =INDEX(Trends!$D$3:$D$404,MATCH(C14,Trends!$C$3:$C$404,0)) -> Decreasing | K14: =IF(Reliability!B12="x","x",(IF(ROUNDUP(Reliability!B12,0)=1,"Very High",IF(ROUNDUP(Reliability!B12,0)=2,"High",IF(ROUNDUP(Reliability!B12,0)=3,"Medium",IF(ROUNDUP(Reliability!B12,0)=4,"Low","Very Low")))))) -> High | L14: =IF(OR(N14="x",M14="x"),"x",ROUND((5-GEOMEAN(((5-M14)/5*4+1),((5-N14)/5*4+1),((5-N14)/5*4+1)))/4*5,1)) -> 2 | M14: ='Impact of the crisis'!N15 -> 2.5 | N14: ='Impact of the crisis'!AB15 -> 1.7 | O14: ='Conditions of people affected'!R15 -> 0.5 | P14: ='Conditions of people affected'!K15 -> 0 | Q14: ='Conditions of people affected'!Q15 -> 1 | R14: =IF(OR(T14="x",S14="x"),S14,ROUND((5-GEOMEAN(((5-S14)/5*4+1),((5-T14)/5*4+1)))/4*5,1)) -> 3 | S14: ='Complexity of the crisis'!X15 -> 2.9 | T14: ='Complexity of the crisis'!AN15 -> 3 | U14: =VLOOKUP(C14,Lists!$C$3:$E$200,3,FALSE) -> Americas | V14: 45015
A15: ='Crisis Indicator Data'!A13 -> Complex crisis in CAR | B15: =Lists!G13 -> Complex crisis | C15: ='Crisis Indicator Data'!C13 -> CAF001 | D15: ='Crisis Indicator Data'!D13 -> CAR | E15: ='Crisis Indicator Data'!E13 -> CAF | F15: ='Crisis Indicator Data'!B13 -> Conflict,Displacement | G15: =IF(OR(O15="x",L15="x"),"x",ROUND((5-GEOMEAN(((5-L15)/5*4+1),((5-O15)/5*4+1),((5-O15)/5*4+1)))/4*3.5+R15*0.3,1)) -> 4.1 | H15: =IF(G15="x","x",ROUNDUP(G15,0)) -> 5 | I15: =IF(O15="x","x",IF(L15="x","x",(IF(H15=5,"Very High",IF(H15=4,"High",IF(H15=3,"Medium",IF(H15=2,"Low","Very Low"))))))) -> Very High | J15: =INDEX(Trends!$D$3:$D$404,MATCH(C15,Trends!$C$3:$C$404,0)) -> Stable | K15: =IF(Reliability!B13="x","x",(IF(ROUNDUP(Reliability!B13,0)=1,"Very High",IF(ROUNDUP(Reliability!B13,0)=2,"High",IF(ROUNDUP(Reliability!B13,0)=3,"Medium",IF(ROUNDUP(Reliability!B13,0)=4,"Low","Very Low")))))) -> High | L15: =IF(OR(N15="x",M15="x"),"x",ROUND((5-GEOMEAN(((5-M15)/5*4+1),((5-N15)/5*4+1),((5-N15)/5*4+1)))/4*5,1)) -> 4.3 | M15: ='Impact of the crisis'!N16 -> 4.4 | N15: ='Impact of the crisis'!AB16 -> 4.2 | O15: ='Conditions of people affected'!R16 -> 4.1 | P15: ='Conditions of people affected'!K16 -> 4.2 | Q15: ='Conditions of people affected'!Q16 -> 4 | R15: =IF(OR(T15="x",S15="x"),S15,ROUND((5-GEOMEAN(((5-S15)/5*4+1),((5-T15)/5*4+1)))/4*5,1)) -> 4 | S15: ='Complexity of the crisis'!X16 -> 3.9 | T15: ='Complexity of the crisis'!AN16 -> 4 | U15: =VLOOKUP(C15,Lists!$C$3:$E$200,3,FALSE) -> Africa | V15: 45019
A16: ='Crisis Indicator Data'!A14 -> Venezuela displacement in Chile | B16: =Lists!G14 -> Venezuelan refugees | C16: ='Crisis Indicator Data'!C14 -> CHL002 | D16: ='Crisis Indicator Data'!D14 -> Chile | E16: ='Crisis Indicator Data'!E14 -> CHL | F16: ='Crisis Indicator Data'!B14 -> Displacement | G16: =IF(OR(O16="x",L16="x"),"x",ROUND((5-GEOMEAN(((5-L16)/5*4+1),((5-O16)/5*4+1),((5-O16)/5*4+1)))/4*3.5+R16*0.3,1)) -> 2.5 | H16: =IF(G16="x","x",ROUNDUP(G16,0)) -> 3 | I16: =IF(O16="x","x",IF(L16="x","x",(IF(H16=5,"Very High",IF(H16=4,"High",IF(H16=3,"Medium",IF(H16=2,"Low","Very Low"))))))) -> Medium | J16: =INDEX(Trends!$D$3:$D$404,MATCH(C16,Trends!$C$3:$C$404,0)) -> Stable | K16: =IF(Reliability!B14="x","x",(IF(ROUNDUP(Reliability!B14,0)=1,"Very High",IF(ROUNDUP(Reliability!B14,0)=2,"High",IF(ROUNDUP(Reliability!B14,0)=3,"Medium",IF(ROUNDUP(Reliability!B14,0)=4,"Low","Very Low")))))) -> Very High | L16: =IF(OR(N16="x",M16="x"),"x",ROUND((5-GEOMEAN(((5-M16)/5*4+1),((5-N16)/5*4+1),((5-N16)/5*4+1)))/4*5,1)) -> 3.7 | M16: ='Impact of the crisis'!N17 -> 4.8 | N16: ='Impact of the crisis'!AB17 -> 2.8 | O16: ='Conditions of people affected'!R17 -> 2.4 | P16: ='Conditions of people affected'!K17 -> 2.8 | Q16: ='Conditions of people affected'!Q17 -> 2 | R16: =IF(OR(T16="x",S16="x"),S16,ROUND((5-GEOMEAN(((5-S16)/5*4+1),((5-T16)/5*4+1)))/4*5,1)) -> 1.7 | S16: ='Complexity of the crisis'!X17 -> 1.3 | T16: ='Complexity of the crisis'!AN17 -> 2 | U16: =VLOOKUP(C16,Lists!$C$3:$E$200,3,FALSE) -> Americas | V16: 44985
... A163: ='Crisis Indicator Data'!A161 -> Complex crisis in Zimbabwe | B163: =Lists!G161 -> Complex crisis | C163: ='Crisis Indicator Data'!C161 -> ZWE001 | D163: ='Crisis Indicator Data'!D161 -> Zimbabwe | E163: ='Crisis Indicator Data'!E161 -> ZWE | F163: ='Crisis Indicator Data'!B161 -> Socio-political,Drought | G163: =IF(OR(O163="x",L163="x"),"x",ROUND((5-GEOMEAN(((5-L163)/5*4+1),((5-O163)/5*4+1),((5-O163)/5*4+1)))/4*3.5+R163*0.3,1)) -> 3.5 | H163: =IF(G163="x","x",ROUNDUP(G163,0)) -> 4 | I163: =IF(O163="x","x",IF(L163="x","x",(IF(H163=5,"Very High",IF(H163=4,"High",IF(H163=3,"Medium",IF(H163=2,"Low","Very Low"))))))) -> High | J163: =INDEX(Trends!$D$3:$D$404,MATCH(C163,Trends!$C$3:$C$404,0)) -> Decreasing | K163: =IF(Reliability!B161="x","x",(IF(ROUNDUP(Reliability!B161,0)=1,"Very High",IF(ROUNDUP(Reliability!B161,0)=2,"High",IF(ROUNDUP(Reliability!B161,0)=3,"Medium",IF(ROUNDUP(Reliability!B161,0)=4,"Low","Very Low")))))) -> Very High | L163: =IF(OR(N163="x",M163="x"),"x",ROUND((5-GEOMEAN(((5-M163)/5*4+1),((5-N163)/5*4+1),((5-N163)/5*4+1)))/4*5,1)) -> 3.9 | M163: ='Impact of the crisis'!N164 -> 4.6 | N163: ='Impact of the crisis'!AB164 -> 3.5 | O163: ='Conditions of people affected'!R164 -> 3.55 | P163: ='Conditions of people affected'!K164 -> 4.1 | Q163: ='Conditions of people affected'!Q164 -> 3 | R163: =IF(OR(T163="x",S163="x"),S163,ROUND((5-GEOMEAN(((5-S163)/5*4+1),((5-T163)/5*4+1)))/4*5,1)) -> 3 | S163: ='Complexity of the crisis'!X164 -> 3 | T163: ='Complexity of the crisis'!AN164 -> 3 | U163: =VLOOKUP(C163,Lists!$C$3:$E$200,3,FALSE) -> Africa | V163: 45039

Sheet INFORM Severity - all crises
A1: ="INFORM Severity Index - all crises. Release: "&About!$A$5&"" -> INFORM Severity Index - all crises. Release: April 2023
A2: CRISIS | B2: CRISIS ID | C2: COUNTRY | D2: ISO3 | E2: DRIVERS | F2: INFORM Severity Index | G2: INFORM Severity category | H2: INFORM Severity category | I2: Trend (last 3 months) | J2: Reliability | K2: Impact of the crisis | L2: Geographical | M2: Human | N2: Conditions of people affected | O2: People in need | P2: Concentration of conditions | Q2: Complexity of the crisis | R2: Society and safety | S2: Operating environment | T2: Regions | U2: Last updated
A3: Weights
A4: (a-z) | D4: (a-z) | F4: (1-5) | G4: (1-5) | H4: (Very Low-Very High) | I4: (Decreasing-Stable-Increasing) | J4: (Very Low-Very High) | K4: (1-5) | L4: (1-5) | M4: (1-5) | N4: (1-5) | O4: (1-5) | P4: (1-5) | Q4: (1-5) | R4: (1-5) | S4: (1-5)
A5: {=IFERROR(INDEX(Lists!$B$2:$B$200,SMALL(IF(Lists!$I$2:$I$200="Individual",ROW(Lists!$B$2:$B$200)),ROW(1:1))-1,1),"")} -> Complex crisis in Afghanistan | B5: =VLOOKUP(A5,Lists!$B$2:$G$200,2,FALSE) -> AFG001 | C5: =VLOOKUP(B5,'INFORM Severity - hidden'!$C$5:$D$200,2,FALSE) -> Afghanistan | D5: =VLOOKUP(A5,Lists!$B$2:$G$200,3,FALSE) -> AFG | E5: =VLOOKUP(A5,Lists!$B$2:$G$200,5,FALSE) -> Conflict,Violence,Displacement,Drought,Earthquake,Socio-political | F5: =IF(OR(N5="x",K5="x"),"x",ROUND((5-GEOMEAN(((5-K5)/5*4+1),((5-N5)/5*4+1),((5-N5)/5*4+1)))/4*3.5+Q5*0.3,1)) -> 4.4 | G5: =IF(F5="x","x",ROUNDUP(F5,0)) -> 5 | H5: =IF(N5="x","x",IF(K5="x","x",(IF(G5=5,"Very High",IF(G5=4,"High",IF(G5=3,"Medium",IF(G5=2,"Low","Very Low"))))))) -> Very High | I5: =INDEX(Trends!$D$3:$D$404,MATCH(B5,Trends!$C$3:$C$404,0)) -> Stable | J5: =VLOOKUP($B5,Reliability!$A$3:$I$170,9,FALSE) -> High | K5: =IF(OR(M5="x",L5="x"),"x",ROUND((5-GEOMEAN(((5-L5)/5*4+1),((5-M5)/5*4+1),((5-M5)/5*4+1)))/4*5,1)) -> 4.6 | L5: =VLOOKUP($B5,'Impact of the crisis'!$C$6:$N$170,12,FALSE) -> 4.9 | M5: =VLOOKUP($B5,'Impact of the crisis'!$C$6:$AB$170,26,FALSE) -> 4.4 | N5: =VLOOKUP($B5,'Conditions of people affected'!$C$6:$R$170,16,FALSE) -> 4.5 | O5: =VLOOKUP($B5,'Conditions of people affected'!$C$6:$R$170,9,FALSE) -> 5 | P5: =VLOOKUP($B5,'Conditions of people affected'!$C$6:$R$170,15,FALSE) -> 4 | Q5: =IF(OR(S5="x",R5="x"),R5,ROUND((5-GEOMEAN(((5-R5)/5*4+1),((5-S5)/5*4+1)))/4*5,1)) -> 4.2 | R5: =VLOOKUP($B5,'Complexity of the crisis'!$C$6:$AN$170,22,FALSE) -> 3.9 | S5: =VLOOKUP($B5,'Complexity of the crisis'!$C$6:$AN$170,38,FALSE) -> 4.5 | T5: =VLOOKUP(B5,Lists!$C$3:$E$163,3,FALSE) -> Asia | U5: =VLOOKUP(B5,'INFORM Severity - hidden'!$C$5:$V$200,20,FALSE) -> 45046
A6: {=IFERROR(INDEX(Lists!$B$2:$B$200,SMALL(IF(Lists!$I$2:$I$200="Individual",ROW(Lists!$B$2:$B$200)),ROW(2:2))-1,1),"")} -> Drought in South-West Angola | B6: =VLOOKUP(A6,Lists!$B$2:$G$200,2,FALSE) -> AGO002 | C6: =VLOOKUP(B6,'INFORM Severity - hidden'!$C$5:$D$200,2,FALSE) -> Angola | D6: =VLOOKUP(A6,Lists!$B$2:$G$200,3,FALSE) -> AGO | E6: =VLOOKUP(A6,Lists!$B$2:$G$200,5,FALSE) -> Drought | F6: =IF(OR(N6="x",K6="x"),"x",ROUND((5-GEOMEAN(((5-K6)/5*4+1),((5-N6)/5*4+1),((5-N6)/5*4+1)))/4*3.5+Q6*0.3,1)) -> 3.1 | G6: =IF(F6="x","x",ROUNDUP(F6,0)) -> 4 | H6: =IF(N6="x","x",IF(K6="x","x",(IF(G6=5,"Very High",IF(G6=4,"High",IF(G6=3,"Medium",IF(G6=2,"Low","Very Low"))))))) -> High | I6: =INDEX(Trends!$D$3:$D$404,MATCH(B6,Trends!$C$3:$C$404,0)) -> Stable | J6: =VLOOKUP($B6,Reliability!$A$3:$I$170,9,FALSE) -> High | K6: =IF(OR(M6="x",L6="x"),"x",ROUND((5-GEOMEAN(((5-L6)/5*4+1),((5-M6)/5*4+1),((5-M6)/5*4+1)))/4*5,1)) -> 2.8 | L6: =VLOOKUP($B6,'Impact of the crisis'!$C$6:$N$170,12,FALSE) -> 3.7 | M6: =VLOOKUP($B6,'Impact of the crisis'!$C$6:$AB$170,26,FALSE) -> 2.2 | N6: =VLOOKUP($B6,'Conditions of people affected'!$C$6:$R$170,16,FALSE) -> 3.85 | O6: =VLOOKUP($B6,'Conditions of people affected'!$C$6:$R$170,9,FALSE) -> 3.7 | P6: =VLOOKUP($B6,'Conditions of people affected'!$C$6:$R$170,15,FALSE) -> 4 | Q6: =IF(OR(S6="x",R6="x"),R6,ROUND((5-GEOMEAN(((5-R6)/5*4+1),((5-S6)/5*4+1)))/4*5,1)) -> 2.2 | R6: =VLOOKUP($B6,'Complexity of the crisis'!$C$6:$AN$170,22,FALSE) -> 3.1 | S6: =VLOOKUP($B6,'Complexity of the crisis'!$C$6:$AN$170,38,FALSE) -> 1 | T6: =VLOOKUP(B6,Lists!$C$3:$E$163,3,FALSE) -> Africa | U6: =VLOOKUP(B6,'INFORM Severity - hidden'!$C$5:$V$200,20,FALSE) -> 45043
A7: {=IFERROR(INDEX(Lists!$B$2:$B$200,SMALL(IF(Lists!$I$2:$I$200="Individual",ROW(Lists!$B$2:$B$200)),ROW(3:3))-1,1),"")} -> Nagorno-Karabakh Conflict in Armenia | B7: =VLOOKUP(A7,Lists!$B$2:$G$200,2,FALSE) -> ARM002 | C7: =VLOOKUP(B7,'INFORM Severity - hidden'!$C$5:$D$200,2,FALSE) -> Armenia | D7: =VLOOKUP(A7,Lists!$B$2:$G$200,3,FALSE) -> ARM | E7: =VLOOKUP(A7,Lists!$B$2:$G$200,5,FALSE) -> Conflict,Displacement | F7: =IF(OR(N7="x",K7="x"),"x",ROUND((5-GEOMEAN(((5-K7)/5*4+1),((5-N7)/5*4+1),((5-N7)/5*4+1)))/4*3.5+Q7*0.3,1)) -> 1.2 | G7: =IF(F7="x","x",ROUNDUP(F7,0)) -> 2 | H7: =IF(N7="x","x",IF(K7="x","x",(IF(G7=5,"Very High",IF(G7=4,"High",IF(G7=3,"Medium",IF(G7=2,"Low","Very Low"))))))) -> Low | I7: =INDEX(Trends!$D$3:$D$404,MATCH(B7,Trends!$C$3:$C$404,0)) -> Decreasing | J7: =VLOOKUP($B7,Reliability!$A$3:$I$170,9,FALSE) -> Medium | K7: =IF(OR(M7="x",L7="x"),"x",ROUND((5-GEOMEAN(((5-L7)/5*4+1),((5-M7)/5*4+1),((5-M7)/5*4+1)))/4*5,1)) -> 1.6 | L7: =VLOOKUP($B7,'Impact of the crisis'!$C$6:$N$170,12,FALSE) -> 1.3 | M7: =VLOOKUP($B7,'Impact of the crisis'!$C$6:$AB$170,26,FALSE) -> 1.8 | N7: =VLOOKUP($B7,'Conditions of people affected'!$C$6:$R$170,16,FALSE) -> 0.85 | O7: =VLOOKUP($B7,'Conditions of people affected'!$C$6:$R$170,9,FALSE) -> 0.7 | P7: =VLOOKUP($B7,'Conditions of people affected'!$C$6:$R$170,15,FALSE) -> 1 | Q7: =IF(OR(S7="x",R7="x"),R7,ROUND((5-GEOMEAN(((5-R7)/5*4+1),((5-S7)/5*4+1)))/4*5,1)) -> 1.4 | R7: =VLOOKUP($B7,'Complexity of the crisis'!$C$6:$AN$170,22,FALSE) -> 1.8 | S7: =VLOOKUP($B7,'Complexity of the crisis'!$C$6:$AN$170,38,FALSE) -> 1 | T7: =VLOOKUP(B7,Lists!$C$3:$E$163,3,FALSE) -> Middle east | U7: =VLOOKUP(B7,'INFORM Severity - hidden'!$C$5:$V$200,20,FALSE) -> 45046
A8: {=IFERROR(INDEX(Lists!$B$2:$B$200,SMALL(IF(Lists!$I$2:$I$200="Individual",ROW(Lists!$B$2:$B$200)),ROW(4:4))-1,1),"")} -> Nagorno-Karabakh conflict in Azerbaijan | B8: =VLOOKUP(A8,Lists!$B$2:$G$200,2,FALSE) -> AZE002 | C8: =VLOOKUP(B8,'INFORM Severity - hidden'!$C$5:$D$200,2,FALSE) -> Azerbaijan | D8: =VLOOKUP(A8,Lists!$B$2:$G$200,3,FALSE) -> AZE | E8: =VLOOKUP(A8,Lists!$B$2:$G$200,5,FALSE) -> Conflict,Displacement | F8: =IF(OR(N8="x",K8="x"),"x",ROUND((5-GEOMEAN(((5-K8)/5*4+1),((5-N8)/5*4+1),((5-N8)/5*4+1)))/4*3.5+Q8*0.3,1)) -> 1.8 | G8: =IF(F8="x","x",ROUNDUP(F8,0)) -> 2 | H8: =IF(N8="x","x",IF(K8="x","x",(IF(G8=5,"Very High",IF(G8=4,"High",IF(G8=3,"Medium",IF(G8=2,"Low","Very Low"))))))) -> Low | I8: =INDEX(Trends!$D$3:$D$404,MATCH(B8,Trends!$C$3:$C$404,0)) -> Stable | J8: =VLOOKUP($B8,Reliability!$A$3:$I$170,9,FALSE) -> Low | K8: =IF(OR(M8="x",L8="x"),"x",ROUND((5-GEOMEAN(((5-L8)/5*4+1),((5-M8)/5*4+1),((5-M8)/5*4+1)))/4*5,1)) -> 2.6 | L8: =VLOOKUP($B8,'Impact of the crisis'!$C$6:$N$170,12,FALSE) -> 1.8 | M8: =VLOOKUP($B8,'Impact of the crisis'!$C$6:$AB$170,26,FALSE) -> 3 | N8: =VLOOKUP($B8,'Conditions of people affected'!$C$6:$R$170,16,FALSE) -> 1 | O8: =VLOOKUP($B8,'Conditions of people affected'!$C$6:$R$170,9,FALSE) -> 0 | P8: =VLOOKUP($B8,'Conditions of people affected'!$C$6:$R$170,15,FALSE) -> 2 | Q8: =IF(OR(S8="x",R8="x"),R8,ROUND((5-GEOMEAN(((5-R8)/5*4+1),((5-S8)/5*4+1)))/4*5,1)) -> 2.3 | R8: =VLOOKUP($B8,'Complexity of the crisis'!$C$6:$AN$170,22,FALSE) -> 2.5 | S8: =VLOOKUP($B8,'Complexity of the crisis'!$C$6:$AN$170,38,FALSE) -> 2 | T8: =VLOOKUP(B8,Lists!$C$3:$E$163,3,FALSE) -> Middle east | U8: =VLOOKUP(B8,'INFORM Severity - hidden'!$C$5:$V$200,20,FALSE) -> 45046
A9: {=IFERROR(INDEX(Lists!$B$2:$B$200,SMALL(IF(Lists!$I$2:$I$200="Individual",ROW(Lists!$B$2:$B$200)),ROW(5:5))-1,1),"")} -> Complex in Burundi | B9: =VLOOKUP(A9,Lists!$B$2:$G$200,2,FALSE) -> BDI001 | C9: =VLOOKUP(B9,'INFORM Severity - hidden'!$C$5:$D$200,2,FALSE) -> Burundi | D9: =VLOOKUP(A9,Lists!$B$2:$G$200,3,FALSE) -> BDI | E9: =VLOOKUP(A9,Lists!$B$2:$G$200,5,FALSE) -> Violence,Displacement,Floods | F9: =IF(OR(N9="x",K9="x"),"x",ROUND((5-GEOMEAN(((5-K9)/5*4+1),((5-N9)/5*4+1),((5-N9)/5*4+1)))/4*3.5+Q9*0.3,1)) -> 3.5 | G9: =IF(F9="x","x",ROUNDUP(F9,0)) -> 4 | H9: =IF(N9="x","x",IF(K9="x","x",(IF(G9=5,"Very High",IF(G9=4,"High",IF(G9=3,"Medium",IF(G9=2,"Low","Very Low"))))))) -> High | I9: =INDEX(Trends!$D$3:$D$404,MATCH(B9,Trends!$C$3:$C$404,0)) -> Stable | J9: =VLOOKUP($B9,Reliability!$A$3:$I$170,9,FALSE) -> Very High | K9: =IF(OR(M9="x",L9="x"),"x",ROUND((5-GEOMEAN(((5-L9)/5*4+1),((5-M9)/5*4+1),((5-M9)/5*4+1)))/4*5,1)) -> 3.9 | L9: =VLOOKUP($B9,'Impact of the crisis'!$C$6:$N$170,12,FALSE) -> 4 | M9: =VLOOKUP($B9,'Impact of the crisis'!$C$6:$AB$170,26,FALSE) -> 3.8 | N9: =VLOOKUP($B9,'Conditions of people affected'!$C$6:$R$170,16,FALSE) -> 3.4 | O9: =VLOOKUP($B9,'Conditions of people affected'!$C$6:$R$170,9,FALSE) -> 3.8 | P9: =VLOOKUP($B9,'Conditions of people affected'!$C$6:$R$170,15,FALSE) -> 3 | Q9: =IF(OR(S9="x",R9="x"),R9,ROUND((5-GEOMEAN(((5-R9)/5*4+1),((5-S9)/5*4+1)))/4*5,1)) -> 3.3 | R9: =VLOOKUP($B9,'Complexity of the crisis'!$C$6:$AN$170,22,FALSE) -> 3 | S9: =VLOOKUP($B9,'Complexity of the crisis'!$C$6:$AN$170,38,FALSE) -> 3.5 | T9: =VLOOKUP(B9,Lists!$C$3:$E$163,3,FALSE) -> Africa | U9: =VLOOKUP(B9,'INFORM Severity - hidden'!$C$5:$V$200,20,FALSE) -> 45002
A10: {=IFERROR(INDEX(Lists!$B$2:$B$200,SMALL(IF(Lists!$I$2:$I$200="Individual",ROW(Lists!$B$2:$B$200)),ROW(6:6))-1,1),"")} -> Conflict in Burkina Faso | B10: =VLOOKUP(A10,Lists!$B$2:$G$200,2,FALSE) -> BFA002 | C10: =VLOOKUP(B10,'INFORM Severity - hidden'!$C$5:$D$200,2,FALSE) -> Burkina Faso | D10: =VLOOKUP(A10,Lists!$B$2:$G$200,3,FALSE) -> BFA | E10: =VLOOKUP(A10,Lists!$B$2:$G$200,5,FALSE) -> Conflict,Displacement,Violence | F10: =IF(OR(N10="x",K10="x"),"x",ROUND((5-GEOMEAN(((5-K10)/5*4+1),((5-N10)/5*4+1),((5-N10)/5*4+1)))/4*3.5+Q10*0.3,1)) -> 4 | G10: =IF(F10="x","x",ROUNDUP(F10,0)) -> 4 | H10: =IF(N10="x","x",IF(K10="x","x",(IF(G10=5,"Very High",IF(G10=4,"High",IF(G10=3,"Medium",IF(G10=2,"Low","Very Low"))))))) -> High | I10: =INDEX(Trends!$D$3:$D$404,MATCH(B10,Trends!$C$3:$C$404,0)) -> Increasing | J10: =VLOOKUP($B10,Reliability!$A$3:$I$170,9,FALSE) -> High | K10: =IF(OR(M10="x",L10="x"),"x",ROUND((5-GEOMEAN(((5-L10)/5*4+1),((5-M10)/5*4+1),((5-M10)/5*4+1)))/4*5,1)) -> 4.2 | L10: =VLOOKUP($B10,'Impact of the crisis'!$C$6:$N$170,12,FALSE) -> 2.5 | M10: =VLOOKUP($B10,'Impact of the crisis'!$C$6:$AB$170,26,FALSE) -> 4.7 | N10: =VLOOKUP($B10,'Conditions of people affected'!$C$6:$R$170,16,FALSE) -> 4.15 | O10: =VLOOKUP($B10,'Conditions of people affected'!$C$6:$R$170,9,FALSE) -> 4.3 | P10: =VLOOKUP($B10,'Conditions of people affected'!$C$6:$R$170,15,FALSE) -> 4 | Q10: =IF(OR(S10="x",R10="x"),R10,ROUND((5-GEOMEAN(((5-R10)/5*4+1),((5-S10)/5*4+1)))/4*5,1)) -> 3.6 | R10: =VLOOKUP($B10,'Complexity of the crisis'!$C$6:$AN$170,22,FALSE) -> 3.2 | S10: =VLOOKUP($B10,'Complexity of the crisis'!$C$6:$AN$170,38,FALSE) -> 4 | T10: =VLOOKUP(B10,Lists!$C$3:$E$163,3,FALSE) -> Africa | U10: =VLOOKUP(B10,'INFORM Severity - hidden'!$C$5:$V$200,20,FALSE) -> 45019
A11: {=IFERROR(INDEX(Lists!$B$2:$B$200,SMALL(IF(Lists!$I$2:$I$200="Individual",ROW(Lists!$B$2:$B$200)),ROW(7:7))-1,1),"")} -> Rohingya refugee crisis | B11: =VLOOKUP(A11,Lists!$B$2:$G$200,2,FALSE) -> BGD002 | C11: =VLOOKUP(B11,'INFORM Severity - hidden'!$C$5:$D$200,2,FALSE) -> Bangladesh | D11: =VLOOKUP(A11,Lists!$B$2:$G$200,3,FALSE) -> BGD | E11: =VLOOKUP(A11,Lists!$B$2:$G$200,5,FALSE) -> Conflict,Violence,Displacement | F11: =IF(OR(N11="x",K11="x"),"x",ROUND((5-GEOMEAN(((5-K11)/5*4+1),((5-N11)/5*4+1),((5-N11)/5*4+1)))/4*3.5+Q11*0.3,1)) -> 3 | G11: =IF(F11="x","x",ROUNDUP(F11,0)) -> 3 | H11: =IF(N11="x","x",IF(K11="x","x",(IF(G11=5,"Very High",IF(G11=4,"High",IF(G11=3,"Medium",IF(G11=2,"Low","Very Low"))))))) -> Medium | I11: =INDEX(Trends!$D$3:$D$404,MATCH(B11,Trends!$C$3:$C$404,0)) -> Stable | J11: =VLOOKUP($B11,Reliability!$A$3:$I$170,9,FALSE) -> Very High | K11: =IF(OR(M11="x",L11="x"),"x",ROUND((5-GEOMEAN(((5-L11)/5*4+1),((5-M11)/5*4+1),((5-M11)/5*4+1)))/4*5,1)) -> 2.9 | L11: =VLOOKUP($B11,'Impact of the crisis'!$C$6:$N$170,12,FALSE) -> 0.2 | M11: =VLOOKUP($B11,'Impact of the crisis'!$C$6:$AB$170,26,FALSE) -> 3.8 | N11: =VLOOKUP($B11,'Conditions of people affected'!$C$6:$R$170,16,FALSE) -> 3.3 | O11: =VLOOKUP($B11,'Conditions of people affected'!$C$6:$R$170,9,FALSE) -> 3.6 | P11: =VLOOKUP($B11,'Conditions of people affected'!$C$6:$R$170,15,FALSE) -> 3 | Q11: =IF(OR(S11="x",R11="x"),R11,ROUND((5-GEOMEAN(((5-R11)/5*4+1),((5-S11)/5*4+1)))/4*5,1)) -> 2.6 | R11: =VLOOKUP($B11,'Complexity of the crisis'!$C$6:$AN$170,22,FALSE) -> 2.6 | S11: =VLOOKUP($B11,'Complexity of the crisis'!$C$6:$AN$170,38,FALSE) -> 2.5 | T11: =VLOOKUP(B11,Lists!$C$3:$E$163,3,FALSE) -> Asia | U11: =VLOOKUP(B11,'INFORM Severity - hidden'!$C$5:$V$200,20,FALSE) -> 45043
A12: {=IFERROR(INDEX(Lists!$B$2:$B$200,SMALL(IF(Lists!$I$2:$I$200="Individual",ROW(Lists!$B$2:$B$200)),ROW(8:8))-1,1),"")} -> Venezuela displacement in Brazil | B12: =VLOOKUP(A12,Lists!$B$2:$G$200,2,FALSE) -> BRA002 | C12: =VLOOKUP(B12,'INFORM Severity - hidden'!$C$5:$D$200,2,FALSE) -> Brazil | D12: =VLOOKUP(A12,Lists!$B$2:$G$200,3,FALSE) -> BRA | E12: =VLOOKUP(A12,Lists!$B$2:$G$200,5,FALSE) -> Displacement | F12: =IF(OR(N12="x",K12="x"),"x",ROUND((5-GEOMEAN(((5-K12)/5*4+1),((5-N12)/5*4+1),((5-N12)/5*4+1)))/4*3.5+Q12*0.3,1)) -> 2.7 | G12: =IF(F12="x","x",ROUNDUP(F12,0)) -> 3 | H12: =IF(N12="x","x",IF(K12="x","x",(IF(G12=5,"Very High",IF(G12=4,"High",IF(G12=3,"Medium",IF(G12=2,"Low","Very Low"))))))) -> Medium | I12: =INDEX(Trends!$D$3:$D$404,MATCH(B12,Trends!$C$3:$C$404,0)) -> Increasing | J12: =VLOOKUP($B12,Reliability!$A$3:$I$170,9,FALSE) -> Very High | K12: =IF(OR(M12="x",L12="x"),"x",ROUND((5-GEOMEAN(((5-L12)/5*4+1),((5-M12)/5*4+1),((5-M12)/5*4+1)))/4*5,1)) -> 3.8 | L12: =VLOOKUP($B12,'Impact of the crisis'!$C$6:$N$170,12,FALSE) -> 4.4 | M12: =VLOOKUP($B12,'Impact of the crisis'!$C$6:$AB$170,26,FALSE) -> 3.5 | N12: =VLOOKUP($B12,'Conditions of people affected'!$C$6:$R$170,16,FALSE) -> 1.75 | O12: =VLOOKUP($B12,'Conditions of people affected'!$C$6:$R$170,9,FALSE) -> 2.5 | P12: =VLOOKUP($B12,'Conditions of people affected'!$C$6:$R$170,15,FALSE) -> 1 | Q12: =IF(OR(S12="x",R12="x"),R12,ROUND((5-GEOMEAN(((5-R12)/5*4+1),((5-S12)/5*4+1)))/4*5,1)) -> 3 | R12: =VLOOKUP($B12,'Complexity of the crisis'!$C$6:$AN$170,22,FALSE) -> 2.9 | S12: =VLOOKUP($B12,'Complexity of the crisis'!$C$6:$AN$170,38,FALSE) -> 3 | T12: =VLOOKUP(B12,Lists!$C$3:$E$163,3,FALSE) -> Americas | U12: =VLOOKUP(B12,'INFORM Severity - hidden'!$C$5:$V$200,20,FALSE) -> 45015
A13: {=IFERROR(INDEX(Lists!$B$2:$B$200,SMALL(IF(Lists!$I$2:$I$200="Individual",ROW(Lists!$B$2:$B$200)),ROW(9:9))-1,1),"")} -> Floods in rainy season 2022 | B13: =VLOOKUP(A13,Lists!$B$2:$G$200,2,FALSE) -> BRA003 | C13: =VLOOKUP(B13,'INFORM Severity - hidden'!$C$5:$D$200,2,FALSE) -> Brazil | D13: =VLOOKUP(A13,Lists!$B$2:$G$200,3,FALSE) -> BRA | E13: =VLOOKUP(A13,Lists!$B$2:$G$200,5,FALSE) -> Floods | F13: =IF(OR(N13="x",K13="x"),"x",ROUND((5-GEOMEAN(((5-K13)/5*4+1),((5-N13)/5*4+1),((5-N13)/5*4+1)))/4*3.5+Q13*0.3,1)) -> 1.6 | G13: =IF(F13="x","x",ROUNDUP(F13,0)) -> 2 | H13: =IF(N13="x","x",IF(K13="x","x",(IF(G13=5,"Very High",IF(G13=4,"High",IF(G13=3,"Medium",IF(G13=2,"Low","Very Low"))))))) -> Low | I13: =INDEX(Trends!$D$3:$D$404,MATCH(B13,Trends!$C$3:$C$404,0)) -> Decreasing | J13: =VLOOKUP($B13,Reliability!$A$3:$I$170,9,FALSE) -> High | K13: =IF(OR(M13="x",L13="x"),"x",ROUND((5-GEOMEAN(((5-L13)/5*4+1),((5-M13)/5*4+1),((5-M13)/5*4+1)))/4*5,1)) -> 2 | L13: =VLOOKUP($B13,'Impact of the crisis'!$C$6:$N$170,12,FALSE) -> 2.5 | M13: =VLOOKUP($B13,'Impact of the crisis'!$C$6:$AB$170,26,FALSE) -> 1.7 | N13: =VLOOKUP($B13,'Conditions of people affected'!$C$6:$R$170,16,FALSE) -> 0.5 | O13: =VLOOKUP($B13,'Conditions of people affected'!$C$6:$R$170,9,FALSE) -> 0 | P13: =VLOOKUP($B13,'Conditions of people affected'!$C$6:$R$170,15,FALSE) -> 1 | Q13: =IF(OR(S13="x",R13="x"),R13,ROUND((5-GEOMEAN(((5-R13)/5*4+1),((5-S13)/5*4+1)))/4*5,1)) -> 3 | R13: =VLOOKUP($B13,'Complexity of the crisis'!$C$6:$AN$170,22,FALSE) -> 2.9 | S13: =VLOOKUP($B13,'Complexity of the crisis'!$C$6:$AN$170,38,FALSE) -> 3 | T13: =VLOOKUP(B13,Lists!$C$3:$E$163,3,FALSE) -> Americas | U13: =VLOOKUP(B13,'INFORM Severity - hidden'!$C$5:$V$200,20,FALSE) -> 45015
A14: {=IFERROR(INDEX(Lists!$B$2:$B$200,SMALL(IF(Lists!$I$2:$I$200="Individual",ROW(Lists!$B$2:$B$200)),ROW(10:10))-1,1),"")} -> Complex crisis in CAR | B14: =VLOOKUP(A14,Lists!$B$2:$G$200,2,FALSE) -> CAF001 | C14: =VLOOKUP(B14,'INFORM Severity - hidden'!$C$5:$D$200,2,FALSE) -> CAR | D14: =VLOOKUP(A14,Lists!$B$2:$G$200,3,FALSE) -> CAF | E14: =VLOOKUP(A14,Lists!$B$2:$G$200,5,FALSE) -> Conflict,Displacement | F14: =IF(OR(N14="x",K14="x"),"x",ROUND((5-GEOMEAN(((5-K14)/5*4+1),((5-N14)/5*4+1),((5-N14)/5*4+1)))/4*3.5+Q14*0.3,1)) -> 4.1 | G14: =IF(F14="x","x",ROUNDUP(F14,0)) -> 5 | H14: =IF(N14="x","x",IF(K14="x","x",(IF(G14=5,"Very High",IF(G14=4,"High",IF(G14=3,"Medium",IF(G14=2,"Low","Very Low"))))))) -> Very High | I14: =INDEX(Trends!$D$3:$D$404,MATCH(B14,Trends!$C$3:$C$404,0)) -> Stable | J14: =VLOOKUP($B14,Reliability!$A$3:$I$170,9,FALSE) -> High | K14: =IF(OR(M14="x",L14="x"),"x",ROUND((5-GEOMEAN(((5-L14)/5*4+1),((5-M14)/5*4+1),((5-M14)/5*4+1)))/4*5,1)) -> 4.3 | L14: =VLOOKUP($B14,'Impact of the crisis'!$C$6:$N$170,12,FALSE) -> 4.4 | M14: =VLOOKUP($B14,'Impact of the crisis'!$C$6:$AB$170,26,FALSE) -> 4.2 | N14: =VLOOKUP($B14,'Conditions of people affected'!$C$6:$R$170,16,FALSE) -> 4.1 | O14: =VLOOKUP($B14,'Conditions of people affected'!$C$6:$R$170,9,FALSE) -> 4.2 | P14: =VLOOKUP($B14,'Conditions of people affected'!$C$6:$R$170,15,FALSE) -> 4 | Q14: =IF(OR(S14="x",R14="x"),R14,ROUND((5-GEOMEAN(((5-R14)/5*4+1),((5-S14)/5*4+1)))/4*5,1)) -> 4 | R14: =VLOOKUP($B14,'Complexity of the crisis'!$C$6:$AN$170,22,FALSE) -> 3.9 | S14: =VLOOKUP($B14,'Complexity of the crisis'!$C$6:$AN$170,38,FALSE) -> 4 | T14: =VLOOKUP(B14,Lists!$C$3:$E$163,3,FALSE) -> Africa | U14: =VLOOKUP(B14,'INFORM Severity - hidden'!$C$5:$V$200,20,FALSE) -> 45019
A15: {=IFERROR(INDEX(Lists!$B$2:$B$200,SMALL(IF(Lists!$I$2:$I$200="Individual",ROW(Lists!$B$2:$B$200)),ROW(11:11))-1,1),"")} -> Venezuela displacement in Chile | B15: =VLOOKUP(A15,Lists!$B$2:$G$200,2,FALSE) -> CHL002 | C15: =VLOOKUP(B15,'INFORM Severity - hidden'!$C$5:$D$200,2,FALSE) -> Chile | D15: =VLOOKUP(A15,Lists!$B$2:$G$200,3,FALSE) -> CHL | E15: =VLOOKUP(A15,Lists!$B$2:$G$200,5,FALSE) -> Displacement | F15: =IF(OR(N15="x",K15="x"),"x",ROUND((5-GEOMEAN(((5-K15)/5*4+1),((5-N15)/5*4+1),((5-N15)/5*4+1)))/4*3.5+Q15*0.3,1)) -> 2.5 | G15: =IF(F15="x","x",ROUNDUP(F15,0)) -> 3 | H15: =IF(N15="x","x",IF(K15="x","x",(IF(G15=5,"Very High",IF(G15=4,"High",IF(G15=3,"Medium",IF(G15=2,"Low","Very Low"))))))) -> Medium | I15: =INDEX(Trends!$D$3:$D$404,MATCH(B15,Trends!$C$3:$C$404,0)) -> Stable | J15: =VLOOKUP($B15,Reliability!$A$3:$I$170,9,FALSE) -> Very High | K15: =IF(OR(M15="x",L15="x"),"x",ROUND((5-GEOMEAN(((5-L15)/5*4+1),((5-M15)/5*4+1),((5-M15)/5*4+1)))/4*5,1)) -> 3.7 | L15: =VLOOKUP($B15,'Impact of the crisis'!$C$6:$N$170,12,FALSE) -> 4.8 | M15: =VLOOKUP($B15,'Impact of the crisis'!$C$6:$AB$170,26,FALSE) -> 2.8 | N15: =VLOOKUP($B15,'Conditions of people affected'!$C$6:$R$170,16,FALSE) -> 2.4 | O15: =VLOOKUP($B15,'Conditions of people affected'!$C$6:$R$170,9,FALSE) -> 2.8 | P15: =VLOOKUP($B15,'Conditions of people affected'!$C$6:$R$170,15,FALSE) -> 2 | Q15: =IF(OR(S15="x",R15="x"),R15,ROUND((5-GEOMEAN(((5-R15)/5*4+1),((5-S15)/5*4+1)))/4*5,1)) -> 1.7 | R15: =VLOOKUP($B15,'Complexity of the crisis'!$C$6:$AN$170,22,FALSE) -> 1.3 | S15: =VLOOKUP($B15,'Complexity of the crisis'!$C$6:$AN$170,38,FALSE) -> 2 | T15: =VLOOKUP(B15,Lists!$C$3:$E$163,3,FALSE) -> Americas | U15: =VLOOKUP(B15,'INFORM Severity - hidden'!$C$5:$V$200,20,FALSE) -> 44985
A16: {=IFERROR(INDEX(Lists!$B$2:$B$200,SMALL(IF(Lists!$I$2:$I$200="Individual",ROW(Lists!$B$2:$B$200)),ROW(12:12))-1,1),"")} -> Boko Haram in Cameroon | B16: =VLOOKUP(A16,Lists!$B$2:$G$200,2,FALSE) -> CMR002 | C16: =VLOOKUP(B16,'INFORM Severity - hidden'!$C$5:$D$200,2,FALSE) -> Cameroon | D16: =VLOOKUP(A16,Lists!$B$2:$G$200,3,FALSE) -> CMR | E16: =VLOOKUP(A16,Lists!$B$2:$G$200,5,FALSE) -> Conflict | F16: =IF(OR(N16="x",K16="x"),"x",ROUND((5-GEOMEAN(((5-K16)/5*4+1),((5-N16)/5*4+1),((5-N16)/5*4+1)))/4*3.5+Q16*0.3,1)) -> 3.4 | G16: =IF(F16="x","x",ROUNDUP(F16,0)) -> 4 | H16: =IF(N16="x","x",IF(K16="x","x",(IF(G16=5,"Very High",IF(G16=4,"High",IF(G16=3,"Medium",IF(G16=2,"Low","Very Low"))))))) -> High | I16: =INDEX(Trends!$D$3:$D$404,MATCH(B16,Trends!$C$3:$C$404,0)) -> Decreasing | J16: =VLOOKUP($B16,Reliability!$A$3:$I$170,9,FALSE) -> High | K16: =IF(OR(M16="x",L16="x"),"x",ROUND((5-GEOMEAN(((5-L16)/5*4+1),((5-M16)/5*4+1),((5-M16)/5*4+1)))/4*5,1)) -> 2.8 | L16: =VLOOKUP($B16,'Impact of the crisis'!$C$6:$N$170,12,FALSE) -> 1.4 | M16: =VLOOKUP($B16,'Impact of the crisis'!$C$6:$AB$170,26,FALSE) -> 3.4 | N16: =VLOOKUP($B16,'Conditions of people affected'!$C$6:$R$170,16,FALSE) -> 3.75 | O16: =VLOOKUP($B16,'Conditions of people affected'!$C$6:$R$170,9,FALSE) -> 3.5 | P16: =VLOOKUP($B16,'Conditions of people affected'!$C$6:$R$170,15,FALSE) -> 4 | Q16: =IF(OR(S16="x",R16="x"),R16,ROUND((5-GEOMEAN(((5-R16)/5*4+1),((5-S16)/5*4+1)))/4*5,1)) -> 3.3 | R16: =VLOOKUP($B16,'Complexity of the crisis'!$C$6:$AN$170,22,FALSE) -> 3.6 | S16: =VLOOKUP($B16,'Complexity of the crisis'!$C$6:$AN$170,38,FALSE) -> 3 | T16: =VLOOKUP(B16,Lists!$C$3:$E$163,3,FALSE) -> Africa | U16: =VLOOKUP(B16,'INFORM Severity - hidden'!$C$5:$V$200,20,FALSE) -> 45019
A17: {=IFERROR(INDEX(Lists!$B$2:$B$200,SMALL(IF(Lists!$I$2:$I$200="Individual",ROW(Lists!$B$2:$B$200)),ROW(13:13))-1,1),"")} -> Anglophone Crisis in Cameroon | B17: =VLOOKUP(A17,Lists!$B$2:$G$200,2,FALSE) -> CMR003 | C17: =VLOOKUP(B17,'INFORM Severity - hidden'!$C$5:$D$200,2,FALSE) -> Cameroon | D17: =VLOOKUP(A17,Lists!$B$2:$G$200,3,FALSE) -> CMR | E17: =VLOOKUP(A17,Lists!$B$2:$G$200,5,FALSE) -> Conflict | F17: =IF(OR(N17="x",K17="x"),"x",ROUND((5-GEOMEAN(((5-K17)/5*4+1),((5-N17)/5*4+1),((5-N17)/5*4+1)))/4*3.5+Q17*0.3,1)) -> 3.4 | G17: =IF(F17="x","x",ROUNDUP(F17,0)) -> 4 | H17: =IF(N17="x","x",IF(K17="x","x",(IF(G17=5,"Very High",IF(G17=4,"High",IF(G17=3,"Medium",IF(G17=2,"Low","Very Low"))))))) -> High | I17: =INDEX(Trends!$D$3:$D$404,MATCH(B17,Trends!$C$3:$C$404,0)) -> Stable | J17: =VLOOKUP($B17,Reliability!$A$3:$I$170,9,FALSE) -> High | K17: =IF(OR(M17="x",L17="x"),"x",ROUND((5-GEOMEAN(((5-L17)/5*4+1),((5-M17)/5*4+1),((5-M17)/5*4+1)))/4*5,1)) -> 3.2 | L17: =VLOOKUP($B17,'Impact of the crisis'!$C$6:$N$170,12,FALSE) -> 2.6 | M17: =VLOOKUP($B17,'Impact of the crisis'!$C$6:$AB$170,26,FALSE) -> 3.4 | N17: =VLOOKUP($B17,'Conditions of people affected'!$C$6:$R$170,16,FALSE) -> 3.4 | O17: =VLOOKUP($B17,'Conditions of people affected'!$C$6:$R$170,9,FALSE) -> 3.8 | P17: =VLOOKUP($B17,'Conditions of people affected'!$C$6:$R$170,15,FALSE) -> 3 | Q17: =IF(OR(S17="x",R17="x"),R17,ROUND((5-GEOMEAN(((5-R17)/5*4+1),((5-S17)/5*4+1)))/4*5,1)) -> 3.6 | R17: =VLOOKUP($B17,'Complexity of the crisis'!$C$6:$AN$170,22,FALSE) -> 3.6 | S17: =VLOOKUP($B17,'Complexity of the crisis'!$C$6:$AN$170,38,FALSE) -> 3.5 | T17: =VLOOKUP(B17,Lists!$C$3:$E$163,3,FALSE) -> Africa | U17: =VLOOKUP(B17,'INFORM Severity - hidden'!$C$5:$V$200,20,FALSE) -> 45019
A18: {=IFERROR(INDEX(Lists!$B$2:$B$200,SMALL(IF(Lists!$I$2:$I$200="Individual",ROW(Lists!$B$2:$B$200)),ROW(14:14))-1,1),"")} -> CAR refugees in Cameroon | B18: =VLOOKUP(A18,Lists!$B$2:$G$200,2,FALSE) -> CMR004 | C18: =VLOOKUP(B18,'INFORM Severity - hidden'!$C$5:$D$200,2,FALSE) -> Cameroon | D18: =VLOOKUP(A18,Lists!$B$2:$G$200,3,FALSE) -> CMR | E18: =VLOOKUP(A18,Lists!$B$2:$G$200,5,FALSE) -> Conflict,Displacement | F18: =IF(OR(N18="x",K18="x"),"x",ROUND((5-GEOMEAN(((5-K18)/5*4+1),((5-N18)/5*4+1),((5-N18)/5*4+1)))/4*3.5+Q18*0.3,1)) -> 2.9 | G18: =IF(F18="x","x",ROUNDUP(F18,0)) -> 3 | H18: =IF(N18="x","x",IF(K18="x","x",(IF(G18=5,"Very High",IF(G18=4,"High",IF(G18=3,"Medium",IF(G18=2,"Low","Very Low"))))))) -> Medium | I18: =INDEX(Trends!$D$3:$D$404,MATCH(B18,Trends!$C$3:$C$404,0)) -> Stable | J18: =VLOOKUP($B18,Reliability!$A$3:$I$170,9,FALSE) -> Medium | K18: =IF(OR(M18="x",L18="x"),"x",ROUND((5-GEOMEAN(((5-L18)/5*4+1),((5-M18)/5*4+1),((5-M18)/5*4+1)))/4*5,1)) -> 2.5 | L18: =VLOOKUP($B18,'Impact of the crisis'!$C$6:$N$170,12,FALSE) -> 2.4 | M18: =VLOOKUP($B18,'Impact of the crisis'!$C$6:$AB$170,26,FALSE) -> 2.5 | N18: =VLOOKUP($B18,'Conditions of people affected'!$C$6:$R$170,16,FALSE) -> 2.9 | O18: =VLOOKUP($B18,'Conditions of people affected'!$C$6:$R$170,9,FALSE) -> 2.8 | P18: =VLOOKUP($B18,'Conditions of people affected'!$C$6:$R$170,15,FALSE) -> 3 | Q18: =IF(OR(S18="x",R18="x"),R18,ROUND((5-GEOMEAN(((5-R18)/5*4+1),((5-S18)/5*4+1)))/4*5,1)) -> 3.1 | R18: =VLOOKUP($B18,'Complexity of the crisis'!$C$6:$AN$170,22,FALSE) -> 3.6 | S18: =VLOOKUP($B18,'Complexity of the crisis'!$C$6:$AN$170,38,FALSE) -> 2.5 | T18: =VLOOKUP(B18,Lists!$C$3:$E$163,3,FALSE) -> Africa | U18: =VLOOKUP(B18,'INFORM Severity - hidden'!$C$5:$V$200,20,FALSE) -> 45019
A19: {=IFERROR(INDEX(Lists!$B$2:$B$200,SMALL(IF(Lists!$I$2:$I$200="Individual",ROW(Lists!$B$2:$B$200)),ROW(15:15))-1,1),"")} -> Complex crisis in DRC | B19: =VLOOKUP(A19,Lists!$B$2:$G$200,2,FALSE) -> COD001 | C19: =VLOOKUP(B19,'INFORM Severity - hidden'!$C$5:$D$200,2,FALSE) -> DRC | D19: =VLOOKUP(A19,Lists!$B$2:$G$200,3,FALSE) -> COD | E19: =VLOOKUP(A19,Lists!$B$2:$G$200,5,FALSE) -> Conflict,Displacement,Socio-political | F19: =IF(OR(N19="x",K19="x"),"x",ROUND((5-GEOMEAN(((5-K19)/5*4+1),((5-N19)/5*4+1),((5-N19)/5*4+1)))/4*3.5+Q19*0.3,1)) -> 4.5 | G19: =IF(F19="x","x",ROUNDUP(F19,0)) -> 5 | H19: =IF(N19="x","x",IF(K19="x","x",(IF(G19=5,"Very High",IF(G19=4,"High",IF(G19=3,"Medium",IF(G19=2,"Low","Very Low"))))))) -> Very High | I19: =INDEX(Trends!$D$3:$D$404,MATCH(B19,Trends!$C$3:$C$404,0)) -> Increasing | J19: =VLOOKUP($B19,Reliability!$A$3:$I$170,9,FALSE) -> High | K19: =IF(OR(M19="x",L19="x"),"x",ROUND((5-GEOMEAN(((5-L19)/5*4+1),((5-M19)/5*4+1),((5-M19)/5*4+1)))/4*5,1)) -> 4.5 | L19: =VLOOKUP($B19,'Impact of the crisis'!$C$6:$N$170,12,FALSE) -> 5 | M19: =VLOOKUP($B19,'Impact of the crisis'!$C$6:$AB$170,26,FALSE) -> 4.2 | N19: =VLOOKUP($B19,'Conditions of people affected'!$C$6:$R$170,16,FALSE) -> 4.5 | O19: =VLOOKUP($B19,'Conditions of people affected'!$C$6:$R$170,9,FALSE) -> 5 | P19: =VLOOKUP($B19,'Conditions of people affected'!$C$6:$R$170,15,FALSE) -> 4 | Q19: =IF(OR(S19="x",R19="x"),R19,ROUND((5-GEOMEAN(((5-R19)/5*4+1),((5-S19)/5*4+1)))/4*5,1)) -> 4.4 | R19: =VLOOKUP($B19,'Complexity of the crisis'!$C$6:$AN$170,22,FALSE) -> 4.3 | S19: =VLOOKUP($B19,'Complexity of the crisis'!$C$6:$AN$170,38,FALSE) -> 4.5 | T19: =VLOOKUP(B19,Lists!$C$3:$E$163,3,FALSE) -> Africa | U19: =VLOOKUP(B19,'INFORM Severity - hidden'!$C$5:$V$200,20,FALSE) -> 45019
A20: {=IFERROR(INDEX(Lists!$B$2:$B$200,SMALL(IF(Lists!$I$2:$I$200="Individual",ROW(Lists!$B$2:$B$200)),ROW(16:16))-1,1),"")} -> Complex crisis in Congo | B20: =VLOOKUP(A20,Lists!$B$2:$G$200,2,FALSE) -> COG001 | C20: =VLOOKUP(B20,'INFORM Severity - hidden'!$C$5:$D$200,2,FALSE) -> Congo | D20: =VLOOKUP(A20,Lists!$B$2:$G$200,3,FALSE) -> COG | E20: =VLOOKUP(A20,Lists!$B$2:$G$200,5,FALSE) -> Conflict | F20: =IF(OR(N20="x",K20="x"),"x",ROUND((5-GEOMEAN(((5-K20)/5*4+1),((5-N20)/5*4+1),((5-N20)/5*4+1)))/4*3.5+Q20*0.3,1)) -> 2.2 | G20: =IF(F20="x","x",ROUNDUP(F20,0)) -> 3 | H20: =IF(N20="x","x",IF(K20="x","x",(IF(G20=5,"Very High",IF(G20=4,"High",IF(G20=3,"Medium",IF(G20=2,"Low","Very Low"))))))) -> Medium | I20: =INDEX(Trends!$D$3:$D$404,MATCH(B20,Trends!$C$3:$C$404,0)) -> Increasing | J20: =VLOOKUP($B20,Reliability!$A$3:$I$170,9,FALSE) -> High | K20: =IF(OR(M20="x",L20="x"),"x",ROUND((5-GEOMEAN(((5-L20)/5*4+1),((5-M20)/5*4+1),((5-M20)/5*4+1)))/4*5,1)) -> 2.8 | L20: =VLOOKUP($B20,'Impact of the crisis'!$C$6:$N$170,12,FALSE) -> 3.1 | M20: =VLOOKUP($B20,'Impact of the crisis'!$C$6:$AB$170,26,FALSE) -> 2.6 | N20: =VLOOKUP($B20,'Conditions of people affected'!$C$6:$R$170,16,FALSE) -> 2 | O20: =VLOOKUP($B20,'Conditions of people affected'!$C$6:$R$170,9,FALSE) -> 1 | P20: =VLOOKUP($B20,'Conditions of people affected'!$C$6:$R$170,15,FALSE) -> 3 | Q20: =IF(OR(S20="x",R20="x"),R20,ROUND((5-GEOMEAN(((5-R20)/5*4+1),((5-S20)/5*4+1)))/4*5,1)) -> 2.1 | R20: =VLOOKUP($B20,'Complexity of the crisis'!$C$6:$AN$170,22,FALSE) -> 2.9 | S20: =VLOOKUP($B20,'Complexity of the crisis'!$C$6:$AN$170,38,FALSE) -> 1 | T20: =VLOOKUP(B20,Lists!$C$3:$E$163,3,FALSE) -> Africa | U20: =VLOOKUP(B20,'INFORM Severity - hidden'!$C$5:$V$200,20,FALSE) -> 45043
A21: {=IFERROR(INDEX(Lists!$B$2:$B$200,SMALL(IF(Lists!$I$2:$I$200="Individual",ROW(Lists!$B$2:$B$200)),ROW(17:17))-1,1),"")} -> Complex crisis in Colombia | B21: =VLOOKUP(A21,Lists!$B$2:$G$200,2,FALSE) -> COL001 | C21: =VLOOKUP(B21,'INFORM Severity - hidden'!$C$5:$D$200,2,FALSE) -> Colombia | D21: =VLOOKUP(A21,Lists!$B$2:$G$200,3,FALSE) -> COL | E21: =VLOOKUP(A21,Lists!$B$2:$G$200,5,FALSE) -> Socio-political,Conflict,Violence,Floods,Displacement | F21: =IF(OR(N21="x",K21="x"),"x",ROUND((5-GEOMEAN(((5-K21)/5*4+1),((5-N21)/5*4+1),((5-N21)/5*4+1)))/4*3.5+Q21*0.3,1)) -> 4.1 | G21: =IF(F21="x","x",ROUNDUP(F21,0)) -> 5 | H21: =IF(N21="x","x",IF(K21="x","x",(IF(G21=5,"Very High",IF(G21=4,"High",IF(G21=3,"Medium",IF(G21=2,"Low","Very Low"))))))) -> Very High | I21: =INDEX(Trends!$D$3:$D$404,MATCH(B21,Trends!$C$3:$C$404,0)) -> Increasing | J21: =VLOOKUP($B21,Reliability!$A$3:$I$170,9,FALSE) -> Very High | K21: =IF(OR(M21="x",L21="x"),"x",ROUND((5-GEOMEAN(((5-L21)/5*4+1),((5-M21)/5*4+1),((5-M21)/5*4+1)))/4*5,1)) -> 4.5 | L21: =VLOOKUP($B21,'Impact of the crisis'!$C$6:$N$170,12,FALSE) -> 5 | M21: =VLOOKUP($B21,'Impact of the crisis'!$C$6:$AB$170,26,FALSE) -> 4.1 | N21: =VLOOKUP($B21,'Conditions of people affected'!$C$6:$R$170,16,FALSE) -> 4.4 | O21: =VLOOKUP($B21,'Conditions of people affected'!$C$6:$R$170,9,FALSE) -> 4.8 | P21: =VLOOKUP($B21,'Conditions of people affected'!$C$6:$R$170,15,FALSE) -> 4 | Q21: =IF(OR(S21="x",R21="x"),R21,ROUND((5-GEOMEAN(((5-R21)/5*4+1),((5-S21)/5*4+1)))/4*5,1)) -> 3.3 | R21: =VLOOKUP($B21,'Complexity of the crisis'!$C$6:$AN$170,22,FALSE) -> 3.1 | S21: =VLOOKUP($B21,'Complexity of the crisis'!$C$6:$AN$170,38,FALSE) -> 3.5 | T21: =VLOOKUP(B21,Lists!$C$3:$E$163,3,FALSE) -> Americas | U21: =VLOOKUP(B21,'INFORM Severity - hidden'!$C$5:$V$200,20,FALSE) -> 45014
A22: {=IFERROR(INDEX(Lists!$B$2:$B$200,SMALL(IF(Lists!$I$2:$I$200="Individual",ROW(Lists!$B$2:$B$200)),ROW(18:18))-1,1),"")} -> Venezuela displacement in Colombia | B22: =VLOOKUP(A22,Lists!$B$2:$G$200,2,FALSE) -> COL002 | C22: =VLOOKUP(B22,'INFORM Severity - hidden'!$C$5:$D$200,2,FALSE) -> Colombia | D22: =VLOOKUP(A22,Lists!$B$2:$G$200,3,FALSE) -> COL | E22: =VLOOKUP(A22,Lists!$B$2:$G$200,5,FALSE) -> Displacement | F22: =IF(OR(N22="x",K22="x"),"x",ROUND((5-GEOMEAN(((5-K22)/5*4+1),((5-N22)/5*4+1),((5-N22)/5*4+1)))/4*3.5+Q22*0.3,1)) -> 3.7 | G22: =IF(F22="x","x",ROUNDUP(F22,0)) -> 4 | H22: =IF(N22="x","x",IF(K22="x","x",(IF(G22=5,"Very High",IF(G22=4,"High",IF(G22=3,"Medium",IF(G22=2,"Low","Very Low"))))))) -> High | I22: =INDEX(Trends!$D$3:$D$404,MATCH(B22,Trends!$C$3:$C$404,0)) -> Stable | J22: =VLOOKUP($B22,Reliability!$A$3:$I$170,9,FALSE) -> High | K22: =IF(OR(M22="x",L22="x"),"x",ROUND((5-GEOMEAN(((5-L22)/5*4+1),((5-M22)/5*4+1),((5-M22)/5*4+1)))/4*5,1)) -> 4.2 | L22: =VLOOKUP($B22,'Impact of the crisis'!$C$6:$N$170,12,FALSE) -> 4.7 | M22: =VLOOKUP($B22,'Impact of the crisis'!$C$6:$AB$170,26,FALSE) -> 3.9 | N22: =VLOOKUP($B22,'Conditions of people affected'!$C$6:$R$170,16,FALSE) -> 3.8 | O22: =VLOOKUP($B22,'Conditions of people affected'!$C$6:$R$170,9,FALSE) -> 4.6 | P22: =VLOOKUP($B22,'Conditions of people affected'!$C$6:$R$170,15,FALSE) -> 3 | Q22: =IF(OR(S22="x",R22="x"),R22,ROUND((5-GEOMEAN(((5-R22)/5*4+1),((5-S22)/5*4+1)))/4*5,1)) -> 3.3 | R22: =VLOOKUP($B22,'Complexity of the crisis'!$C$6:$AN$170,22,FALSE) -> 3.1 | S22: =VLOOKUP($B22,'Complexity of the crisis'!$C$6:$AN$170,38,FALSE) -> 3.5 | T22: =VLOOKUP(B22,Lists!$C$3:$E$163,3,FALSE) -> Americas | U22: =VLOOKUP(B22,'INFORM Severity - hidden'!$C$5:$V$200,20,FALSE) -> 45026
A23: {=IFERROR(INDEX(Lists!$B$2:$B$200,SMALL(IF(Lists!$I$2:$I$200="Individual",ROW(Lists!$B$2:$B$200)),ROW(19:19))-1,1),"")} -> Nicaraguan refugees in Costa Rica | B23: =VLOOKUP(A23,Lists!$B$2:$G$200,2,FALSE) -> CRI002 | C23: =VLOOKUP(B23,'INFORM Severity - hidden'!$C$5:$D$200,2,FALSE) -> Costa Rica | D23: =VLOOKUP(A23,Lists!$B$2:$G$200,3,FALSE) -> CRI | E23: =VLOOKUP(A23,Lists!$B$2:$G$200,5,FALSE) -> Displacement | F23: =IF(OR(N23="x",K23="x"),"x",ROUND((5-GEOMEAN(((5-K23)/5*4+1),((5-N23)/5*4+1),((5-N23)/5*4+1)))/4*3.5+Q23*0.3,1)) -> 2.1 | G23: =IF(F23="x","x",ROUNDUP(F23,0)) -> 3 | H23: =IF(N23="x","x",IF(K23="x","x",(IF(G23=5,"Very High",IF(G23=4,"High",IF(G23=3,"Medium",IF(G23=2,"Low","Very Low"))))))) -> Medium | I23: =INDEX(Trends!$D$3:$D$404,MATCH(B23,Trends!$C$3:$C$404,0)) -> Stable | J23: =VLOOKUP($B23,Reliability!$A$3:$I$170,9,FALSE) -> High | K23: =IF(OR(M23="x",L23="x"),"x",ROUND((5-GEOMEAN(((5-L23)/5*4+1),((5-M23)/5*4+1),((5-M23)/5*4+1)))/4*5,1)) -> 2.4 | L23: =VLOOKUP($B23,'Impact of the crisis'!$C$6:$N$170,12,FALSE) -> 0.7 | M23: =VLOOKUP($B23,'Impact of the crisis'!$C$6:$AB$170,26,FALSE) -> 3.1 | N23: =VLOOKUP($B23,'Conditions of people affected'!$C$6:$R$170,16,FALSE) -> 2.6 | O23: =VLOOKUP($B23,'Conditions of people affected'!$C$6:$R$170,9,FALSE) -> 2.2 | P23: =VLOOKUP($B23,'Conditions of people affected'!$C$6:$R$170,15,FALSE) -> 3 | Q23: =IF(OR(S23="x",R23="x"),R23,ROUND((5-GEOMEAN(((5-R23)/5*4+1),((5-S23)/5*4+1)))/4*5,1)) -> 1.2 | R23: =VLOOKUP($B23,'Complexity of the crisis'!$C$6:$AN$170,22,FALSE) -> 0.9 | S23: =VLOOKUP($B23,'Complexity of the crisis'!$C$6:$AN$170,38,FALSE) -> 1.5 | T23: =VLOOKUP(B23,Lists!$C$3:$E$163,3,FALSE) -> Americas | U23: =VLOOKUP(B23,'INFORM Severity - hidden'!$C$5:$V$200,20,FALSE) -> 45046
